angel@angel-HP-ProBook-430-G4:~/Documentos/My-games/Pipu-AI$ pip install tensorflow
Defaulting to user installation because normal site-packages is not writeable
Collecting tensorflow
  Using cached tensorflow-2.20.0-cp312-cp312-manylinux_2_17_x86_64.manylinux2014_x86_64.whl.metadata (4.5 kB)
Requirement already satisfied: absl-py>=1.0.0 in /var/data/python/lib/python3.12/site-packages (from tensorflow) (2.3.1)
Collecting astunparse>=1.6.0 (from tensorflow)
  Using cached astunparse-1.6.3-py2.py3-none-any.whl.metadata (4.4 kB)
Collecting flatbuffers>=24.3.25 (from tensorflow)
  Using cached flatbuffers-25.9.23-py2.py3-none-any.whl.metadata (875 bytes)
Collecting gast!=0.5.0,!=0.5.1,!=0.5.2,>=0.2.1 (from tensorflow)
  Using cached gast-0.6.0-py3-none-any.whl.metadata (1.3 kB)
Collecting google_pasta>=0.1.1 (from tensorflow)
  Using cached google_pasta-0.2.0-py3-none-any.whl.metadata (814 bytes)
Collecting libclang>=13.0.0 (from tensorflow)
  Using cached libclang-18.1.1-py2.py3-none-manylinux2010_x86_64.whl.metadata (5.2 kB)
Collecting opt_einsum>=2.3.2 (from tensorflow)
  Using cached opt_einsum-3.4.0-py3-none-any.whl.metadata (6.3 kB)
Requirement already satisfied: packaging in /usr/lib/python3.12/site-packages (from tensorflow) (25.0)
Requirement already satisfied: protobuf>=5.28.0 in /var/data/python/lib/python3.12/site-packages (from tensorflow) (5.29.5)
Requirement already satisfied: requests<3,>=2.21.0 in /var/data/python/lib/python3.12/site-packages (from tensorflow) (2.32.5)
Requirement already satisfied: setuptools in /usr/lib/python3.12/site-packages (from tensorflow) (80.9.0)
Requirement already satisfied: six>=1.12.0 in /usr/lib/python3.12/site-packages (from tensorflow) (1.17.0)
Collecting termcolor>=1.1.0 (from tensorflow)
  Using cached termcolor-3.1.0-py3-none-any.whl.metadata (6.4 kB)
Requirement already satisfied: typing_extensions>=3.6.6 in /var/data/python/lib/python3.12/site-packages (from tensorflow) (4.15.0)
Collecting wrapt>=1.11.0 (from tensorflow)
  Using cached wrapt-1.17.3-cp312-cp312-manylinux1_x86_64.manylinux_2_28_x86_64.manylinux_2_5_x86_64.whl.metadata (6.4 kB)
Requirement already satisfied: grpcio<2.0,>=1.24.3 in /var/data/python/lib/python3.12/site-packages (from tensorflow) (1.75.1)
Collecting tensorboard~=2.20.0 (from tensorflow)
  Using cached tensorboard-2.20.0-py3-none-any.whl.metadata (1.8 kB)
Requirement already satisfied: keras>=3.10.0 in /var/data/python/lib/python3.12/site-packages (from tensorflow) (3.11.3)
Requirement already satisfied: numpy>=1.26.0 in /var/data/python/lib/python3.12/site-packages (from tensorflow) (2.3.4)
Requirement already satisfied: h5py>=3.11.0 in /var/data/python/lib/python3.12/site-packages (from tensorflow) (3.15.0)
Requirement already satisfied: ml_dtypes<1.0.0,>=0.5.1 in /var/data/python/lib/python3.12/site-packages (from tensorflow) (0.5.3)
Requirement already satisfied: charset_normalizer<4,>=2 in /var/data/python/lib/python3.12/site-packages (from requests<3,>=2.21.0->tensorflow) (3.4.4)
Requirement already satisfied: idna<4,>=2.5 in /var/data/python/lib/python3.12/site-packages (from requests<3,>=2.21.0->tensorflow) (3.11)
Requirement already satisfied: urllib3<3,>=1.21.1 in /var/data/python/lib/python3.12/site-packages (from requests<3,>=2.21.0->tensorflow) (2.5.0)
Requirement already satisfied: certifi>=2017.4.17 in /var/data/python/lib/python3.12/site-packages (from requests<3,>=2.21.0->tensorflow) (2025.10.5)
Requirement already satisfied: markdown>=2.6.8 in /usr/lib/python3.12/site-packages (from tensorboard~=2.20.0->tensorflow) (3.9)
Collecting pillow (from tensorboard~=2.20.0->tensorflow)
  Using cached pillow-12.0.0-cp312-cp312-manylinux_2_27_x86_64.manylinux_2_28_x86_64.whl.metadata (8.8 kB)
Collecting tensorboard-data-server<0.8.0,>=0.7.0 (from tensorboard~=2.20.0->tensorflow)
  Using cached tensorboard_data_server-0.7.2-py3-none-manylinux_2_31_x86_64.whl.metadata (1.1 kB)
Collecting werkzeug>=1.0.1 (from tensorboard~=2.20.0->tensorflow)
  Using cached werkzeug-3.1.3-py3-none-any.whl.metadata (3.7 kB)
Requirement already satisfied: wheel<1.0,>=0.23.0 in /usr/lib/python3.12/site-packages (from astunparse>=1.6.0->tensorflow) (0.46.1)
Requirement already satisfied: rich in /var/data/python/lib/python3.12/site-packages (from keras>=3.10.0->tensorflow) (14.2.0)
Requirement already satisfied: namex in /var/data/python/lib/python3.12/site-packages (from keras>=3.10.0->tensorflow) (0.1.0)
Requirement already satisfied: optree in /var/data/python/lib/python3.12/site-packages (from keras>=3.10.0->tensorflow) (0.17.0)
Requirement already satisfied: MarkupSafe>=2.1.1 in /usr/lib/python3.12/site-packages (from werkzeug>=1.0.1->tensorboard~=2.20.0->tensorflow) (3.0.3)
Requirement already satisfied: markdown-it-py>=2.2.0 in /var/data/python/lib/python3.12/site-packages (from rich->keras>=3.10.0->tensorflow) (4.0.0)
Requirement already satisfied: pygments<3.0.0,>=2.13.0 in /usr/lib/python3.12/site-packages (from rich->keras>=3.10.0->tensorflow) (2.19.2)
Requirement already satisfied: mdurl~=0.1 in /var/data/python/lib/python3.12/site-packages (from markdown-it-py>=2.2.0->rich->keras>=3.10.0->tensorflow) (0.1.2)
Downloading tensorflow-2.20.0-cp312-cp312-manylinux_2_17_x86_64.manylinux2014_x86_64.whl (620.7 MB)
   ━━━━━━━━━━━━━━━━━━━━━━━━━━━━━━━━━━━━━━╺━ 593.0/620.7 MB 24.8 MB/s eta 0:00:02
ERROR: Exception:
Traceback (most recent call last):
  File "/usr/lib/python3.12/site-packages/pip/_vendor/urllib3/response.py", line 438, in _error_catcher
    yield
  File "/usr/lib/python3.12/site-packages/pip/_vendor/urllib3/response.py", line 561, in read
    data = self._fp_read(amt) if not fp_closed else b""
           ^^^^^^^^^^^^^^^^^^
  File "/usr/lib/python3.12/site-packages/pip/_vendor/urllib3/response.py", line 527, in _fp_read
    return self._fp.read(amt) if amt is not None else self._fp.read()
           ^^^^^^^^^^^^^^^^^^
  File "/usr/lib/python3.12/site-packages/pip/_vendor/cachecontrol/filewrapper.py", line 102, in read
    self.__buf.write(data)
  File "/usr/lib/python3.12/tempfile.py", line 499, in func_wrapper
    return func(*args, **kwargs)
           ^^^^^^^^^^^^^^^^^^^^^
OSError: [Errno 28] No queda espacio en el dispositivo

During handling of the above exception, another exception occurred:

Traceback (most recent call last):
  File "/usr/lib/python3.12/site-packages/pip/_internal/cli/base_command.py", line 107, in _run_wrapper
    status = _inner_run()
             ^^^^^^^^^^^^
  File "/usr/lib/python3.12/site-packages/pip/_internal/cli/base_command.py", line 98, in _inner_run
    return self.run(options, args)
           ^^^^^^^^^^^^^^^^^^^^^^^
  File "/usr/lib/python3.12/site-packages/pip/_internal/cli/req_command.py", line 71, in wrapper
    return func(self, options, args)
           ^^^^^^^^^^^^^^^^^^^^^^^^^
  File "/usr/lib/python3.12/site-packages/pip/_internal/commands/install.py", line 393, in run
    requirement_set = resolver.resolve(
                      ^^^^^^^^^^^^^^^^^
  File "/usr/lib/python3.12/site-packages/pip/_internal/resolution/resolvelib/resolver.py", line 184, in resolve
    self.factory.preparer.prepare_linked_requirements_more(reqs)
  File "/usr/lib/python3.12/site-packages/pip/_internal/operations/prepare.py", line 564, in prepare_linked_requirements_more
    self._complete_partial_requirements(
  File "/usr/lib/python3.12/site-packages/pip/_internal/operations/prepare.py", line 479, in _complete_partial_requirements
    for link, (filepath, _) in batch_download:
                               ^^^^^^^^^^^^^^
  File "/usr/lib/python3.12/site-packages/pip/_internal/network/download.py", line 184, in batch
    filepath, content_type = self(link, location)
                             ^^^^^^^^^^^^^^^^^^^^
  File "/usr/lib/python3.12/site-packages/pip/_internal/network/download.py", line 195, in __call__
    self._process_response(download, resp)
  File "/usr/lib/python3.12/site-packages/pip/_internal/network/download.py", line 212, in _process_response
    for chunk in chunks:
                 ^^^^^^
  File "/usr/lib/python3.12/site-packages/pip/_internal/cli/progress_bars.py", line 67, in _rich_download_progress_bar
    for chunk in iterable:
                 ^^^^^^^^
  File "/usr/lib/python3.12/site-packages/pip/_internal/network/utils.py", line 65, in response_chunks
    for chunk in response.raw.stream(
                 ^^^^^^^^^^^^^^^^^^^^
  File "/usr/lib/python3.12/site-packages/pip/_vendor/urllib3/response.py", line 622, in stream
    data = self.read(amt=amt, decode_content=decode_content)
           ^^^^^^^^^^^^^^^^^^^^^^^^^^^^^^^^^^^^^^^^^^^^^^^^^
  File "/usr/lib/python3.12/site-packages/pip/_vendor/urllib3/response.py", line 560, in read
    with self._error_catcher():
         ^^^^^^^^^^^^^^^^^^^^^
  File "/usr/lib/python3.12/contextlib.py", line 158, in __exit__
    self.gen.throw(value)
  File "/usr/lib/python3.12/site-packages/pip/_vendor/urllib3/response.py", line 455, in _error_catcher
    raise ProtocolError("Connection broken: %r" % e, e)
pip._vendor.urllib3.exceptions.ProtocolError: ("Connection broken: OSError(28, 'No queda espacio en el dispositivo')", OSError(28, 'No queda espacio en el dispositivo'))
